Workbook
Name Dico: [1]Dico!$A$1:$J$65536
Name Lang: [1]Dico!$AB$1
Name Lang2: [1]Dico!$AD$1
Name Print_Area: Template!$A$1:$AY$65

Sheet Template
F1: =Translation!N4 -> STANDARD OPERATION SHEET ANALYSIS (SOS-A) | AN1: =Translation!N3 -> Langue | AT1: Français
AN2: N° DT
A4: FOR-054-Multi-J | AL4: =ROUNDUP(ROW()/4, 0) -> 1 | AM4: ="/" & MAX(AL:AL) -> /2
A5: =Translation!N5 -> Poste de travail : | AA5: =Translation!N7 -> Produit:
A6: =Translation!N6 -> Activité:
A7: =Translation!N8 -> Équipement de protection personnel (PPE)
A8: =Translation!N9 -> Chaussures de sécurité | G8: =Translation!N10 -> Tenue de travail | L8: =Translation!N11 -> Protection de la tête | Q8: =Translation!N12 -> Gants | V8: =Translation!N13 -> Gilet | AA8: =Translation!N14 -> Lunettes | AF8: =Translation!N15 -> Protection auditive | AK8: =Translation!N16 -> Masque | AP8: =Translation!N17 -> Matière dangereuse | AU8: =Translation!N18 -> Recyclage
A9: 2
A13: =Translation!N19 -> Qu'est-ce qui est interdit et pourquoi ? Comment réagir ? | AP13: =Translation!N20 -> Panoply: | AV13: =Translation!N22 -> Oui | AX13: =Translation!N23 -> Non
AP14: =Translation!N21 -> Piece zone: | AV14: =Translation!N22 -> Oui | AX14: =Translation!N23 -> Non
A15: 3 | AP15: =Translation!N24 -> Couleurs de zonage :
AP16: =Translation!N25 -> A - Très visible | AU16: =Translation!N26 -> B - Visible
AP17: =Translation!N27 -> C - Peut-être visible | AU17: =Translation!N28 -> D - Invisible
A18: =Translation!N29 -> Produits et outils utilisés (rajouter les référence)
A19: 4
A25: =Translation!N30 -> Pictogrammes utilisés : | K25: =Translation!N31 -> Aspect | Q25: =Translation!N32 -> Tactile | W25: =Translation!N33 -> Bruit | AC25: =Translation!N34 -> en secouant | AI25: =Translation!N35 -> Mesure
A26: =Translation!N36 -> Caractéristique spéciale (CS) : caractéristique (produit où process) liée à la sécurité ou aux règles légales, fonction de la pièce. Aucun écart autorisé.
A27: =Translation!N37 -> Révision : | E27: Date: | H27: =Translation!N38 -> Sujet de révision : | AJ27: =Translation!N40 -> Créé par : | AR27: =Translation!N41 -> Validé - Production :
A28: 0 | H28: =Translation!N39 -> Création de documents : | AJ28: =Translation!N44 -> Date : | AR28: =Translation!N44 -> Date :
AJ29: =Translation!N45 -> Signature : | AR29: =Translation!N45 -> Signature :
AJ30: =Translation!N42 -> Validé - Qualité : | AR30: =Translation!N43 -> Validé - HSE :
AJ31: =Translation!N44 -> Date : | AR31: =Translation!N44 -> Date :
AJ32: =Translation!N45 -> Signature : | AR32: =Translation!N45 -> Signature :
F33: =F$1 -> STANDARD OPERATION SHEET ANALYSIS (SOS-A) | J33: =F1 -> STANDARD OPERATION SHEET ANALYSIS (SOS-A) | AN33: N° DT
AN35: =IF($AN$3=0,"",$AN$3)
A36: =A$4 -> FOR-054-Multi-J | AL36: =ROUNDUP((ROW()/33), 0) -> 2 | AM36: ="/" & MAX(AL:AL) -> /2 | AN36: =IF($AN$4=0,"",$AN$4)
A37: =A$5 -> Poste de travail : | G37: =IF($G$5=0,"",$G$5) | AA37: =AA$5 -> Produit: | AF37: =IF($AF$5=0,"",$AF$5)
A38: =A$6 -> Activité: | G38: =IF($G$6=0,"",$G$6)
A39: =Translation!N$46 -> N° Etape Principale : | D39: =Translation!N$47 -> CP/CS : | F39: =Translation!N$48 -> Description du mode opératoire: avec détails écrit | O39: =Translation!N$49 -> Complément du mode opératoire: avec photos si besoin | X39: =Translation!N$50 -> Étapes principales | AG39: =Translation!N$51 -> T/C | AH39: =Translation!N$52 -> Points clés (Comment ?) | AQ39: =Translation!N$53 -> Raison du point clé (Pourquoi ?) : en photos ou schéma et OK/NOK si possible
A64: =Translation!N$40 -> Créé par : | G64: =Translation!N$44 -> Date : | M64: =Translation!N$45 -> Signature : | S64: =Translation!N$41 -> Validé - Production : | X64: =Translation!N$44 -> Date : | AD64: =Translation!N$45 -> Signature : | AK64: =Translation!N$42 -> Validé - Qualité : | AO64: =Translation!N$44 -> Date : | AT64: =Translation!N$45 -> Signature :
A65: =IF($AO$27=0,"",$AO$27) | G65: =IF($AM$28=0,"",$AM$28) | M65: =IF($AM$29=0,"",$AM$29) | S65: =IF($AW$27=0,"",$AW$27) | X65: =IF($AU$28=0,"",$AU$28) | AD65: =IF($AU$29=0,"",$AU$29) | AK65: =IF($AO$30=0,"",$AO$30) | AO65: =IF($AM$31=0,"",$AM$31) | AT65: =IF($AM$32=0,"",$AM$32)

Sheet icons

Sheet Revision History
C1: =Translation!N4 -> STANDARD OPERATION SHEET ANALYSIS (SOS-A) | L1: =Template!A4 -> FOR-054-Multi-J
C4: =Translation!N57 -> Historique des révisions
B7: =Translation!N58 -> Date | D7: =Translation!N59 -> Indice | E7: =Translation!N60 -> Pilote de la modification | H7: =Translation!N61 -> Description de la modification
B8: 45015 | D8: A | E8: BONTEMPS Rémi | H8: Creation
B9: 45056 | D9: B | E9: BONTEMPS Rémi | H9: Addition of multilingual choice list and pictograms update
B10: 45299 | D10: C | E10: BONTEMPS Rémi | H10: Adding German language
B11: 45337 | D11: D | E11: PREZEAU Clément | H11: Correction of formula
B12: 45447 | D12: E | E12: PREZEAU Clément | H12: Adding a macro to add a page to the SOS
B13: 45467 | D13: F | E13: Mohamed KHACHROUM | H13: Adding Spanish language
B14: 45474 | D14: G | E14: PREZEAU Clément | H14: Adding automatic formula + automatic page number
B15: 28/08/20204 | D15: H | E15: Mohamed KHACHROUM | H15: Adding validation HSE
B16: 45555 | D16: I | E16: MATIAS Carlos | H16: Adding Portuguese language
B17: 45755 | D17: J | E17: DZIADOWICZ Bartosz | H17: Adding Polish language

Sheet Translation
A1: Français | C1: English | E1: Slovak | G1: Deutsch | I1: Spanish | K1: Portuguese | M1: Polski | N1: Current selection | O1: Languages
E2: Template | O2: Français
A3: Langue | C3: Language | E3: jazyk | G3: Sprache | I3: Lengua | K3: Linguagem | M3: Język | N3: =IF(Template!$AT$1="Français",A3,IF(Template!$AT$1="English",C3,IF(Template!$AT$1="Slovak",E3,IF(Template!$AT$1="Deutsch",G3,IF(Template!$AT$1="Spanish",I3,IF(Template!$AT$1="Portuguese",K3,IF(Template!$AT$1="Polski",M3,))))))) -> Langue | O3: English
A4: STANDARD OPERATION SHEET ANALYSIS (SOS-A) | C4: STANDARD OPERATION SHEET ANALYSIS (SOS-A) | E4: STANDARD OPERATION SHEET ANALYSIS (SOS-A) | G4: STANDARD OPERATION SHEET ANALYSIS (SOS-A) | I4: HOJA DE OPERACIÓN ESTÁNDAR ANÁLISIS (SOS-A) | K4: STANDARD OPERATION SHEET ANALYSIS (SOS-A) | M4: STANDARDOWY ARKUSZ OPERACYJNY ANALIZA (SAO-A) | N4: =IF(Template!$AT$1="Français",A4,IF(Template!$AT$1="English",C4,IF(Template!$AT$1="Slovak",E4,IF(Template!$AT$1="Deutsch",G4,IF(Template!$AT$1="Spanish",I4,IF(Template!$AT$1="Portuguese",K4,IF(Template!$AT$1="Polski",M4,))))))) -> STANDARD OPERATION SHEET ANALYSIS (SOS-A) | O4: Slovak
A5: Poste de travail : | C5: Work station: | E5: Pracovisko: | G5: Arbeitsplatz: | I5: Estación de trabajo : | K5: Posto de trabalho: | M5: Stanowisko pracy: | N5: =IF(Template!$AT$1="Français",A5,IF(Template!$AT$1="English",C5,IF(Template!$AT$1="Slovak",E5,IF(Template!$AT$1="Deutsch",G5,IF(Template!$AT$1="Spanish",I5,IF(Template!$AT$1="Portuguese",K5,IF(Template!$AT$1="Polski",M5,))))))) -> Poste de travail : | O5: Deutsch
A6: Activité: | C6: Activity: | E6: Činnosť: | G6: Aktivität: | I6: Actividad: | K6: Atividade: | M6: Czynność: | N6: =IF(Template!$AT$1="Français",A6,IF(Template!$AT$1="English",C6,IF(Template!$AT$1="Slovak",E6,IF(Template!$AT$1="Deutsch",G6,IF(Template!$AT$1="Spanish",I6,IF(Template!$AT$1="Portuguese",K6,IF(Template!$AT$1="Polski",M6,))))))) -> Activité: | O6: Spanish
A7: Produit: | C7: Product: | E7: Výrobok: | G7: Produkt: | I7: Producto: | K7: Produto: | M7: Produkt: | N7: =IF(Template!$AT$1="Français",A7,IF(Template!$AT$1="English",C7,IF(Template!$AT$1="Slovak",E7,IF(Template!$AT$1="Deutsch",G7,IF(Template!$AT$1="Spanish",I7,IF(Template!$AT$1="Portuguese",K7,IF(Template!$AT$1="Polski",M7,))))))) -> Produit: | O7: Portuguese
A8: Équipement de protection personnel (PPE) | C8: Personal protection equipment (PPE) | E8: Ochranné pracovné pomôcky | G8: Persönliche Schutzausrüstung (PSA) | I8: Equipo de protección personal (EPP) | K8: Equipamento de proteção individual (EPI) | M8: Środki ochrony indywidualnej (ŚOI) | N8: =IF(Template!$AT$1="Français",A8,IF(Template!$AT$1="English",C8,IF(Template!$AT$1="Slovak",E8,IF(Template!$AT$1="Deutsch",G8,IF(Template!$AT$1="Spanish",I8,IF(Template!$AT$1="Portuguese",K8,IF(Template!$AT$1="Polski",M8,))))))) -> Équipement de protection personnel (PPE) | O8: Polski
A9: Chaussures de sécurité | C9: Safety shoes | E9: Pracovná obuv | G9: Sicherheitsschuhe | I9: Calzado de seguridad | K9: Sapato de segurança | M9: Obuwie ochronne: | N9: =IF(Template!$AT$1="Français",A9,IF(Template!$AT$1="English",C9,IF(Template!$AT$1="Slovak",E9,IF(Template!$AT$1="Deutsch",G9,IF(Template!$AT$1="Spanish",I9,IF(Template!$AT$1="Portuguese",K9,IF(Template!$AT$1="Polski",M9,))))))) -> Chaussures de sécurité
A10: Tenue de travail | C10: Work clothes | E10: Pracovný odev | G10: Arbeitskleidung | I10: Indumentaria de trabajo | K10: Roupa de trabalho | M10: Odzież robocza: | N10: =IF(Template!$AT$1="Français",A10,IF(Template!$AT$1="English",C10,IF(Template!$AT$1="Slovak",E10,IF(Template!$AT$1="Deutsch",G10,IF(Template!$AT$1="Spanish",I10,IF(Template!$AT$1="Portuguese",K10,IF(Template!$AT$1="Polski",M10,))))))) -> Tenue de travail
A11: Protection de la tête | C11: Head protection | E11: Ochrana hlavy | G11: Kopfschutz | I11: Protección de la cabeza | K11: Boné de segurança | M11: Ochrona głowy: | N11: =IF(Template!$AT$1="Français",A11,IF(Template!$AT$1="English",C11,IF(Template!$AT$1="Slovak",E11,IF(Template!$AT$1="Deutsch",G11,IF(Template!$AT$1="Spanish",I11,IF(Template!$AT$1="Portuguese",K11,IF(Template!$AT$1="Polski",M11,))))))) -> Protection de la tête
A12: Gants | C12: Gloves | E12: Rukavice | G12: Handschuhe | I12: Guantes | K12: Luvas | M12: Rękawice: | N12: =IF(Template!$AT$1="Français",A12,IF(Template!$AT$1="English",C12,IF(Template!$AT$1="Slovak",E12,IF(Template!$AT$1="Deutsch",G12,IF(Template!$AT$1="Spanish",I12,IF(Template!$AT$1="Portuguese",K12,IF(Template!$AT$1="Polski",M12,))))))) -> Gants
A13: Gilet | C13: Reflex Vest | E13: Reflexná vesta | G13: Warnweste | I13: Chaleco | K13: Colete refletor | M13: Kamizelka odblaskowa: | N13: =IF(Template!$AT$1="Français",A13,IF(Template!$AT$1="English",C13,IF(Template!$AT$1="Slovak",E13,IF(Template!$AT$1="Deutsch",G13,IF(Template!$AT$1="Spanish",I13,IF(Template!$AT$1="Portuguese",K13,IF(Template!$AT$1="Polski",M13,))))))) -> Gilet
A14: Lunettes | C14: Glasses | E14: Okuliare | G14: Brille | I14: Gafas | K14: Óculos | M14: Okulary | N14: =IF(Template!$AT$1="Français",A14,IF(Template!$AT$1="English",C14,IF(Template!$AT$1="Slovak",E14,IF(Template!$AT$1="Deutsch",G14,IF(Template!$AT$1="Spanish",I14,IF(Template!$AT$1="Portuguese",K14,IF(Template!$AT$1="Polski",M14,))))))) -> Lunettes
A15: Protection auditive | C15: Ear protection | E15: Ochrana sluchu | G15: Gehörschutz | I15: Protección auditiva | K15: Proteção auditiva | M15: Ochrona słuchu: | N15: =IF(Template!$AT$1="Français",A15,IF(Template!$AT$1="English",C15,IF(Template!$AT$1="Slovak",E15,IF(Template!$AT$1="Deutsch",G15,IF(Template!$AT$1="Spanish",I15,IF(Template!$AT$1="Portuguese",K15,IF(Template!$AT$1="Polski",M15,))))))) -> Protection auditive
A16: Masque | C16: Resperator | E16: Respirátor | G16: Maske | I16: Máscara | K16: Máscara | M16: Maseczka: | N16: =IF(Template!$AT$1="Français",A16,IF(Template!$AT$1="English",C16,IF(Template!$AT$1="Slovak",E16,IF(Template!$AT$1="Deutsch",G16,IF(Template!$AT$1="Spanish",I16,IF(Template!$AT$1="Portuguese",K16,IF(Template!$AT$1="Polski",M16,))))))) -> Masque
A17: Matière dangereuse | C17: Dangerous Material | E17: Nebezpečný materiál | G17: Gefährliches Material | I17: Material peligroso | K17: Material perigoso | M17: Materiały niebezpieczne: | N17: =IF(Template!$AT$1="Français",A17,IF(Template!$AT$1="English",C17,IF(Template!$AT$1="Slovak",E17,IF(Template!$AT$1="Deutsch",G17,IF(Template!$AT$1="Spanish",I17,IF(Template!$AT$1="Portuguese",K17,IF(Template!$AT$1="Polski",M17,))))))) -> Matière dangereuse
A18: Recyclage | C18: Recycling | E18: Recyklácia | G18: Recycling | I18: Reciclaje | K18: Reciclagem | M18: Recykling: | N18: =IF(Template!$AT$1="Français",A18,IF(Template!$AT$1="English",C18,IF(Template!$AT$1="Slovak",E18,IF(Template!$AT$1="Deutsch",G18,IF(Template!$AT$1="Spanish",I18,IF(Template!$AT$1="Portuguese",K18,IF(Template!$AT$1="Polski",M18,))))))) -> Recyclage
A19: Qu'est-ce qui est interdit et pourquoi ? Comment réagir ? | C19: Special regulations - What is forbidden and why? How to manage abnormalities? | E19: Zvláštne predpisy - Čo je zakázané a prečo? Čo robiť v prípade abnormalít? | G19: Besondere Regelungen - Was ist verboten und warum? Wie geht man mit Abweichungen um? | I19: ¿Qué está prohibido y por qué? ¿Cómo reaccionar? | K19: Regulamentações especiais - O que é proibido e porquê? Como gerir anomalias? | M19: Specjalne regulacje - Co jest zabronione i dlaczego? Jak zarządzać nieprawidłowościami? | N19: =IF(Template!$AT$1="Français",A19,IF(Template!$AT$1="English",C19,IF(Template!$AT$1="Slovak",E19,IF(Template!$AT$1="Deutsch",G19,IF(Template!$AT$1="Spanish",I19,IF(Template!$AT$1="Portuguese",K19,IF(Template!$AT$1="Polski",M19,))))))) -> Qu'est-ce qui est interdit et pourquoi ? Comment réagir ?
A20: Panoply: | C20: Boundary samples: | E20: Tabuľa nepodarkov: | G20: Grenzmuster: | I20: Panoplia: | K20: Panóplia | M20: Przykłady graniczne: | N20: =IF(Template!$AT$1="Français",A20,IF(Template!$AT$1="English",C20,IF(Template!$AT$1="Slovak",E20,IF(Template!$AT$1="Deutsch",G20,IF(Template!$AT$1="Spanish",I20,IF(Template!$AT$1="Portuguese",K20,IF(Template!$AT$1="Polski",M20,))))))) -> Panoply:
... A29: Produits et outils utilisés (rajouter les référence) | C29: Used materials (reference) | E29: Používaný materiál: | G29: Verwendete Materialien (Hilfsmittel): | I29: Productos y herramientas utilizados (añadir referencias) | K29: Produtos e ferramentas utilizados (referência) | M29: Użyte materiały (referencje) | N29: =IF(Template!$AT$1="Français",A29,IF(Template!$AT$1="English",C29,IF(Template!$AT$1="Slovak",E29,IF(Template!$AT$1="Deutsch",G29,IF(Template!$AT$1="Spanish",I29,IF(Template!$AT$1="Portuguese",K29,IF(Template!$AT$1="Polski",M29,))))))) -> Produits et outils utilisés (rajouter les référence)
A30: Pictogrammes utilisés : | C30: Used pictograms: | E30: Použité piktogramy: | G30: Verwendete Piktogramme: | K30: Pictogramas usados: | M30: Użyte piktogramy: | N30: =IF(Template!$AT$1="Français",A30,IF(Template!$AT$1="English",C30,IF(Template!$AT$1="Slovak",E30,IF(Template!$AT$1="Deutsch",G30,IF(Template!$AT$1="Spanish",I30,IF(Template!$AT$1="Portuguese",K30,IF(Template!$AT$1="Polski",M30,))))))) -> Pictogrammes utilisés :
A31: Aspect | C31: Aspect | E31: aspekt | G31: Ansicht | I31: Aspecto | K31: Aspeto | M31: Aspekt | N31: =IF(Template!$AT$1="Français",A31,IF(Template!$AT$1="English",C31,IF(Template!$AT$1="Slovak",E31,IF(Template!$AT$1="Deutsch",G31,IF(Template!$AT$1="Spanish",I31,IF(Template!$AT$1="Portuguese",K31,IF(Template!$AT$1="Polski",M31,))))))) -> Aspect
A32: Tactile | C32: Tactile | E32: hmatový | G32: Taktil | I32: Táctil | K32: Tátil | M32: Dotyk | N32: =IF(Template!$AT$1="Français",A32,IF(Template!$AT$1="English",C32,IF(Template!$AT$1="Slovak",E32,IF(Template!$AT$1="Deutsch",G32,IF(Template!$AT$1="Spanish",I32,IF(Template!$AT$1="Portuguese",K32,IF(Template!$AT$1="Polski",M32,))))))) -> Tactile
A33: Bruit | C33: Noise | E33: hluk | G33: Geräusch | I33: Bruit | K33: Barulho | M33: Hałas | N33: =IF(Template!$AT$1="Français",A33,IF(Template!$AT$1="English",C33,IF(Template!$AT$1="Slovak",E33,IF(Template!$AT$1="Deutsch",G33,IF(Template!$AT$1="Spanish",I33,IF(Template!$AT$1="Portuguese",K33,IF(Template!$AT$1="Polski",M33,))))))) -> Bruit
A34: en secouant | C34: by movement | E34: Pohybom | G34: durch Bewegung | I34: tembloroso | K34: Por movimento | M34: Ruch | N34: =IF(Template!$AT$1="Français",A34,IF(Template!$AT$1="English",C34,IF(Template!$AT$1="Slovak",E34,IF(Template!$AT$1="Deutsch",G34,IF(Template!$AT$1="Spanish",I34,IF(Template!$AT$1="Portuguese",K34,IF(Template!$AT$1="Polski",M34,))))))) -> en secouant
A35: Mesure | C35: Measure | E35: opatrenie | G35: Messung | I35: Medir | K35: Medição | M35: Pomiar | N35: =IF(Template!$AT$1="Français",A35,IF(Template!$AT$1="English",C35,IF(Template!$AT$1="Slovak",E35,IF(Template!$AT$1="Deutsch",G35,IF(Template!$AT$1="Spanish",I35,IF(Template!$AT$1="Portuguese",K35,IF(Template!$AT$1="Polski",M35,))))))) -> Mesure
A36: Caractéristique spéciale (CS) : caractéristique (produit où process) liée à la sécurité ou aux règles légales, fonction de la pièce. Aucun écart autorisé. | C36: Special characteristic (SC): characteristic (product or process), which is related to safety or regulatory rules, function of part. No deviation alowed. | E36: Špeciálna charakteristika (CS): charakteristika, ktorá sa dotýka bezpečnosti / zákonných predpisov, práceschopnosti, funkcie, výkonu výrobku. Nemôže byť schválená žiadna výnimka. | G36: Besonderes Merkmal (BM): Merkmal (Produkt oder Prozess), das sich auf Sicherheits- oder Regulierungsvorschriften, Funktion des Teils bezieht. Keine Abweichung erlaubt. | I36: Característica especial (SC): característica (producto o proceso) relacionada con la seguridad o las regulaciones legales, función de la pieza. | K36: Caracteristicas especiais (CE): Caracterisitica (produto ou processo) que está relacionada com normas de segurança ou regulamentares, função da peça. Nenhum desvio permitido. | M36: Charakterystyka specjalna (SC): charakterystyka (produktu lub procesu), która jest związana z bezpieczeństwem lub przepisami regulacyjnymi, funkcją części. Nie dopuszcza się żadnych odchyleń. | N36: =IF(Template!$AT$1="Français",A36,IF(Template!$AT$1="English",C36,IF(Template!$AT$1="Slovak",E36,IF(Template!$AT$1="Deutsch",G36,IF(Template!$AT$1="Spanish",I36,IF(Template!$AT$1="Portuguese",K36,IF(Template!$AT$1="Polski",M36,))))))) -> Caractéristique spéciale (CS) : caractéristique (produit où process) liée à la sécurité ou aux règles légales, fonction de la pièce. Aucun écart autorisé.
A37: Révision : | C37: Revision : | E37: Revízia: | G37: Revision | I37: Revisión: | K37: Revisão: | M37: Rewizja: | N37: =IF(Template!$AT$1="Français",A37,IF(Template!$AT$1="English",C37,IF(Template!$AT$1="Slovak",E37,IF(Template!$AT$1="Deutsch",G37,IF(Template!$AT$1="Spanish",I37,IF(Template!$AT$1="Portuguese",K37,IF(Template!$AT$1="Polski",M37,))))))) -> Révision :
A38: Sujet de révision : | C38: Revision subject: | E38: Predmet revízie: | G38: Art der Änderung: | I38: Objeto de revisión: | K38: Assunto de revisão: | M38: Temat rewizji: | N38: =IF(Template!$AT$1="Français",A38,IF(Template!$AT$1="English",C38,IF(Template!$AT$1="Slovak",E38,IF(Template!$AT$1="Deutsch",G38,IF(Template!$AT$1="Spanish",I38,IF(Template!$AT$1="Portuguese",K38,IF(Template!$AT$1="Polski",M38,))))))) -> Sujet de révision :
A39: Création de documents : | C39: Document creation | E39: Vytvorenie dokumentu | G39: Erstellung des Dokumentes: | I39: Creación de documentos: | K39: Criação do documento: | M39: Utworzenie dokumentu: | N39: =IF(Template!$AT$1="Français",A39,IF(Template!$AT$1="English",C39,IF(Template!$AT$1="Slovak",E39,IF(Template!$AT$1="Deutsch",G39,IF(Template!$AT$1="Spanish",I39,IF(Template!$AT$1="Portuguese",K39,IF(Template!$AT$1="Polski",M39,))))))) -> Création de documents :
A40: Créé par : | C40: Created by: | E40: Vytvoril | G40: Erstellt von: | I40: Creado por: | K40: Criado por: | M40: Utworzone przez: | N40: =IF(Template!$AT$1="Français",A40,IF(Template!$AT$1="English",C40,IF(Template!$AT$1="Slovak",E40,IF(Template!$AT$1="Deutsch",G40,IF(Template!$AT$1="Spanish",I40,IF(Template!$AT$1="Portuguese",K40,IF(Template!$AT$1="Polski",M40,))))))) -> Créé par :
A41: Validé - Production : | C41: Validation - Production | E41: Schválil - Výroba | G41: Validierung - Produktion | I41: Validado - Producción: | K41: Validação - Produção | M41: Walidacja - Produkcja | N41: =IF(Template!$AT$1="Français",A41,IF(Template!$AT$1="English",C41,IF(Template!$AT$1="Slovak",E41,IF(Template!$AT$1="Deutsch",G41,IF(Template!$AT$1="Spanish",I41,IF(Template!$AT$1="Portuguese",K41,IF(Template!$AT$1="Polski",M41,))))))) -> Validé - Production :
A42: Validé - Qualité : | C42: Validation - Quality | E42: Schválil - Kvalita | G42: Validierung - Qualität | I42: Validado - Calidad: | K42: Validação - Qualidade | M42: Walidacja - Jakość | N42: =IF(Template!$AT$1="Français",A42,IF(Template!$AT$1="English",C42,IF(Template!$AT$1="Slovak",E42,IF(Template!$AT$1="Deutsch",G42,IF(Template!$AT$1="Spanish",I42,IF(Template!$AT$1="Portuguese",K42,IF(Template!$AT$1="Polski",M42,))))))) -> Validé - Qualité :
... A53: Raison du point clé (Pourquoi ?) : en photos ou schéma et OK/NOK si possible | C53: key points reason (Why?) : Pictures, OK/NOK | E53: Dóvod klúčového bodu (Prečo?): Obrázky, OK/NOK | G53: Grund für Schlüsselpunkte (Warum?): Bilder, OK / NOK | I53: Motivo del punto clave (¿Por qué?): en fotos o diagrama y OK/NOK si es posible | K53: Razão do Ponto-chave (Porquê) : Fotos, OK/NOK | M53: Przyczyna kluczowym punktów (Dlaczego?): Zdjęcia OK/NOK | N53: =IF(Template!$AT$1="Français",A53,IF(Template!$AT$1="English",C53,IF(Template!$AT$1="Slovak",E53,IF(Template!$AT$1="Deutsch",G53,IF(Template!$AT$1="Spanish",I53,IF(Template!$AT$1="Portuguese",K53,IF(Template!$AT$1="Polski",M53,))))))) -> Raison du point clé (Pourquoi ?) : en photos ou schéma et OK/NOK si possible
N54: =IF(Template!$AT$1="Français",A54,IF(Template!$AT$1="English",C54,IF(Template!$AT$1="Slovak",E54,IF(Template!$AT$1="Deutsch",G54,IF(Template!$AT$1="Spanish",I54,IF(Template!$AT$1="Portuguese",K54,IF(Template!$AT$1="Polski",M54,))))))) -> 0
N55: =IF(Template!$AT$1="Français",A55,IF(Template!$AT$1="English",C55,IF(Template!$AT$1="Slovak",E55,IF(Template!$AT$1="Deutsch",G55,IF(Template!$AT$1="Spanish",I55,IF(Template!$AT$1="Portuguese",K55,IF(Template!$AT$1="Polski",M55,))))))) -> 0
E56: Revision history | N56: =IF(Template!$AT$1="Français",A56,IF(Template!$AT$1="English",C56,IF(Template!$AT$1="Slovak",E56,IF(Template!$AT$1="Deutsch",G56,IF(Template!$AT$1="Spanish",I56,IF(Template!$AT$1="Portuguese",K56,IF(Template!$AT$1="Polski",M56,))))))) -> 0
A57: Historique des révisions | C57: Revision history | E57: História revízií | G57: Änderungshistorie | I57: Historial de revisiones | K57: Histórico das revisões | M57: Historia rewizji | N57: =IF(Template!$AT$1="Français",A57,IF(Template!$AT$1="English",C57,IF(Template!$AT$1="Slovak",E57,IF(Template!$AT$1="Deutsch",G57,IF(Template!$AT$1="Spanish",I57,IF(Template!$AT$1="Portuguese",K57,IF(Template!$AT$1="Polski",M57,))))))) -> Historique des révisions
A58: Date | C58: Date | E58: Dátum | G58: Datum | I58: Fecha | K58: Data | M58: Data | N58: =IF(Template!$AT$1="Français",A58,IF(Template!$AT$1="English",C58,IF(Template!$AT$1="Slovak",E58,IF(Template!$AT$1="Deutsch",G58,IF(Template!$AT$1="Spanish",I58,IF(Template!$AT$1="Portuguese",K58,IF(Template!$AT$1="Polski",M58,))))))) -> Date
...
